<?xml version="1.0"?>
<robot name="bambot">

  <material name="green">
    <color rgba="0.06 0.4 0.1 1.0" />
  </material>
  <material name="black">
    <color rgba="0.06 0.1 0.1 1.0" />
  </material>

  <link name="base_link">
    <visual>
      <geometry>
        <mesh filename="/home/duvvuri/bambot_ws/src/Prep_PS_UGV_robo/gazebo_spawn_pkg/urdf/bambot_assets/Bambot_Body.stl" scale="0.001 0.001 0.001" />
      </geometry>
      <origin xyz="-0.5 0 0.4" rpy="0 0 0" />
      <material name="green" />
    </visual>

    <collision>
      <geometry>
        <box size="0.45 0.45 0.2"/>
      </geometry>
      <origin xyz="-0.25 -0.25 0.05" rpy="0 0 0" />
    </collision>
  </link>

  <joint name="R_to_base" type="fixed">
    <parent link="base_link" />
    <child link="R_base" />
    <origin xyz="-0.005 -0.585 0.67" rpy="0 3.14158 3.14159" />
  </joint>

  <link name="R_base">
    <inertial>
      <origin xyz="-0.14932 -0.16812 0.065966" rpy="0 0 0" />
      <mass value="0.147" />
      <inertia ixx="0.000114686" ixy="-4.59787e-07" ixz="4.97151e-06" 
               iyy="0.000136117" iyz="9.75275e-08" izz="0.000130364" />
    </inertial>
    
    <visual>
      <origin xyz="-0.169402 -0.168167 0.0300817" rpy="1.5708 -1.67685e-15 1.5708" />
      <geometry>
        <mesh filename="/home/duvvuri/bambot_ws/src/Prep_PS_UGV_robo/gazebo_spawn_pkg/urdf/assets/base_motor_holder_so101_v1.stl" />
      </geometry>
      <material name="green" />
    </visual>
    <visual>
      <origin xyz="-0.169402 -0.168068 0.0300817" rpy="1.5708 -1.6144e-15 1.5708" />
      <geometry>
        <mesh filename="/home/duvvuri/bambot_ws/src/Prep_PS_UGV_robo/gazebo_spawn_pkg/urdf/assets/base_so101_v2.stl" />
      </geometry>
      <material name="green" />
    </visual>
    <visual>
      <origin xyz="-0.136702 -0.168068 0.0761817" rpy="-8.21148e-16 7.84513e-18 1.249e-15" />
      <geometry>
        <mesh filename="/home/duvvuri/bambot_ws/src/Prep_PS_UGV_robo/gazebo_spawn_pkg/urdf/assets/sts3215_03a_v1.stl" />
      </geometry>
      <material name="black" />
    </visual>
    <visual>
      <origin xyz="-0.19402 -0.168267 0.0798817" rpy="1.5708 -1.35493e-14 1.5708" />
      <geometry>
        <mesh filename="/home/duvvuri/bambot_ws/src/Prep_PS_UGV_robo/gazebo_spawn_pkg/urdf/assets/waveshare_mounting_plate_so101_v2.stl" />
      </geometry>
      <material name="green" />
    </visual>
    
    <collision>
      <geometry>
        <box size="0.08 0.05 0.08"/>
      </geometry>
      <origin xyz="-0.17 -0.168 0.065" rpy="0 0 0" />
    </collision>
  </link>

  <link name="R_baseframe">
    <inertial>
      <mass value="1e-9" />
      <inertia ixx="1e-9" ixy="0" ixz="0" iyy="1e-9" iyz="0" izz="1e-9" />
    </inertial>
  </link>

  <joint name="R_baseframe_frame" type="fixed">
    <origin xyz="-0.163038 -0.168068 0.0324817" rpy="1.6144e-15 7.84513e-18 1.33799e-15" />
    <parent link="R_base" />
    <child link="R_baseframe" />
  </joint>

  <link name="R_shoulder">
    <inertial>
      <origin xyz="-0.0307604 -1.66727e-05 -0.0252713" rpy="0 0 0" />
      <mass value="0.100006" />
      <inertia ixx="8.3759e-05" ixy="7.55525e-08" ixz="-1.16342e-06" 
               iyy="8.10403e-05" iyz="1.54663e-07" izz="2.39783e-05" />
    </inertial>
    
    <visual>
      <origin xyz="-0.0303992 0.000422241 -0.0417" rpy="1.5708 1.5708 0" />
      <geometry>
        <mesh filename="/home/duvvuri/bambot_ws/src/Prep_PS_UGV_robo/gazebo_spawn_pkg/urdf/assets/sts3215_03a_v1.stl" />
      </geometry>
      <material name="black" />
    </visual>
    <visual>
      <origin xyz="-0.0675992 -0.000177759 0.0158499" rpy="1.5708 -1.5708 0" />
      <geometry>
        <mesh filename="/home/duvvuri/bambot_ws/src/Prep_PS_UGV_robo/gazebo_spawn_pkg/urdf/assets/motor_holder_so101_base_v1.stl" />
      </geometry>
      <material name="green" />
    </visual>
    <visual>
      <origin xyz="0.0122008 2.22413e-05 0.0464" rpy="-1.5708 2.35221e-33 0" />
      <geometry>
        <mesh filename="/home/duvvuri/bambot_ws/src/Prep_PS_UGV_robo/gazebo_spawn_pkg/urdf/assets/rotation_pitch_so101_v1.stl" />
      </geometry>
      <material name="green" />
    </visual>
    
    <collision>
      <geometry>
        <box size="0.06 0.04 0.06"/>
      </geometry>
      <origin xyz="-0.03 0 0" rpy="0 0 0" />
    </collision>
  </link>

  <link name="R_upper_arm">
    <inertial>
      <origin xyz="-0.0898471 -0.00838224 0.0184089" rpy="0 0 0" />
      <mass value="0.103" />
      <inertia ixx="4.08002e-05" ixy="-1.97819e-05" ixz="-4.03016e-08" 
               iyy="0.000147318" iyz="8.97326e-09" izz="0.000142487" />
    </inertial>
    
    <visual>
      <origin xyz="-0.11257 -0.0155 0.0187" rpy="-3.14159 -5.27356e-16 -1.5708" />
      <geometry>
        <mesh filename="/home/duvvuri/bambot_ws/src/Prep_PS_UGV_robo/gazebo_spawn_pkg/urdf/assets/sts3215_03a_v1.stl" />
      </geometry>
      <material name="black" />
    </visual>
    <visual>
      <origin xyz="-0.065085 0.012 0.0182" rpy="3.14159 -0 -1.30911e-30" />
      <geometry>
        <mesh filename="/home/duvvuri/bambot_ws/src/Prep_PS_UGV_robo/gazebo_spawn_pkg/urdf/assets/upper_arm_so101_v1.stl" />
      </geometry>
      <material name="green" />
    </visual>
    
    <collision>
      <geometry>
        <box size="0.12 0.03 0.04"/>
      </geometry>
      <origin xyz="-0.06 0 0.018" rpy="0 0 0" />
    </collision>
  </link>

  <link name="R_lower_arm">
    <inertial>
      <origin xyz="-0.0980701 0.00324376 0.0182831" rpy="0 0 0" />
      <mass value="0.104" />
      <inertia ixx="2.87438e-05" ixy="7.41152e-06" ixz="1.26409e-06" 
               iyy="0.000159844" iyz="-4.90188e-08" izz="0.00014529" />
    </inertial>
    
    <visual>
      <origin xyz="-0.0648499 -0.032 0.0182" rpy="3.14159 -0 6.67202e-31" />
      <geometry>
        <mesh filename="/home/duvvuri/bambot_ws/src/Prep_PS_UGV_robo/gazebo_spawn_pkg/urdf/assets/under_arm_so101_v1.stl" />
      </geometry>
      <material name="green" />
    </visual>
    <visual>
      <origin xyz="-0.0648499 -0.032 0.018" rpy="-3.14159 -2.55351e-15 -2.56146e-31" />
      <geometry>
        <mesh filename="/home/duvvuri/bambot_ws/src/Prep_PS_UGV_robo/gazebo_spawn_pkg/urdf/assets/motor_holder_so101_wrist_v1.stl" />
      </geometry>
      <material name="green" />
    </visual>
    <visual>
      <origin xyz="-0.1224 0.0052 0.0187" rpy="-3.14159 -7.88861e-31 -3.14159" />
      <geometry>
        <mesh filename="/home/duvvuri/bambot_ws/src/Prep_PS_UGV_robo/gazebo_spawn_pkg/urdf/assets/sts3215_03a_v1.stl" />
      </geometry>
      <material name="black" />
    </visual>
    
    <collision>
      <geometry>
        <box size="0.13 0.04 0.04"/>
      </geometry>
      <origin xyz="-0.09 -0.01 0.018" rpy="0 0 0" />
    </collision>
  </link>

  <link name="R_wrist">
    <inertial>
      <origin xyz="-0.000103312 -0.0386143 0.0281156" rpy="0 0 0" />
      <mass value="0.079" />
      <inertia ixx="3.68263e-05" ixy="1.7893e-08" ixz="-5.28128e-08" 
               iyy="2.5391e-05" iyz="3.6412e-06" izz="2.1e-05" />
    </inertial>
    
    <visual>
      <origin xyz="5.55112e-17 -0.0424 0.0306" rpy="1.5708 1.5708 0" />
      <geometry>
        <mesh filename="/home/duvvuri/bambot_ws/src/Prep_PS_UGV_robo/gazebo_spawn_pkg/urdf/assets/sts3215_03a_no_horn_v1.stl" />
      </geometry>
      <material name="black" />
    </visual>
    <visual>
      <origin xyz="0 -0.028 0.0181" rpy="-1.5708 -1.5708 0" />
      <geometry>
        <mesh filename="/home/duvvuri/bambot_ws/src/Prep_PS_UGV_robo/gazebo_spawn_pkg/urdf/assets/wrist_roll_pitch_so101_v2.stl" />
      </geometry>
      <material name="green" />
    </visual>
    
    <collision>
      <geometry>
        <cylinder radius="0.025" length="0.05"/>
      </geometry>
      <origin xyz="0 -0.03 0.03" rpy="0 0 0" />
    </collision>
  </link>

  <link name="R_gripper">
    <inertial>
      <origin xyz="0.000213627 0.000245138 -0.025187" rpy="0 0 0" />
      <mass value="0.087" />
      <inertia ixx="2.75087e-05" ixy="-3.35241e-07" ixz="-5.7352e-06" iyy="4.33657e-05"
        iyz="-5.17847e-08" izz="3.45059e-05" />
    </inertial>
    <visual>
      <origin xyz="0.0077 0.0001 -0.0234" rpy="-1.5708 -5.19179e-17 -1.66533e-16" />
      <geometry>
        <mesh filename="/home/duvvuri/bambot_ws/src/Prep_PS_UGV_robo/gazebo_spawn_pkg/urdf/assets/sts3215_03a_v1.stl" />
      </geometry>
      <material name="black" />
    </visual>
    <collision>
      <origin xyz="0.0077 0.0001 -0.0234" rpy="-1.5708 -5.19179e-17 -1.66533e-16" />
      <geometry>
        <mesh filename="/home/duvvuri/bambot_ws/src/Prep_PS_UGV_robo/gazebo_spawn_pkg/urdf/assets/sts3215_03a_v1.stl" />
      </geometry>
    </collision>
    <visual>
      <origin xyz="0 -0.000218214 0.000949706" rpy="-3.14159 -5.55112e-17 0" />
      <geometry>
        <mesh filename="/home/duvvuri/bambot_ws/src/Prep_PS_UGV_robo/gazebo_spawn_pkg/urdf/assets/wrist_roll_follower_so101_v1.stl" />
      </geometry>
      <material name="green" />
    </visual>
    <collision>
      <origin xyz="0 -0.000218214 0.000949706" rpy="-3.14159 -5.55112e-17 0" />
      <geometry>
        <mesh filename="/home/duvvuri/bambot_ws/src/Prep_PS_UGV_robo/gazebo_spawn_pkg/urdf/assets/wrist_roll_follower_so101_v1.stl" />
      </geometry>
    </collision>
  </link>

  <link name="R_gripperframe">
    <inertial>
      <mass value="1e-9" />
      <inertia ixx="1e-9" ixy="0" ixz="0" iyy="1e-9" iyz="0" izz="1e-9" />
    </inertial>
  </link>

  <joint name="R_gripperframe_frame" type="fixed">
    <origin xyz="-0.0079 -0.000218121 -0.0981274" rpy="-0 1.5708 0" />
    <parent link="R_gripper" />
    <child link="R_gripperframe" />
  </joint>

  <link name="R_moving_jaw_so101_v1">
    <inertial>
      <origin xyz="-0.00157495 -0.0300244 0.0192755" rpy="0 0 0" />
      <mass value="0.012" />
      <inertia ixx="6.61427e-06" ixy="-3.19807e-07" ixz="-5.90717e-09" 
               iyy="1.89032e-06" iyz="-1.09945e-07" izz="5.28738e-06" />
    </inertial>
    
    <visual>
      <origin xyz="-5.55112e-17 0 0.0189" rpy="9.53145e-17 6.93889e-18 1.24077e-24" />
      <geometry>
        <mesh filename="/home/duvvuri/bambot_ws/src/Prep_PS_UGV_robo/gazebo_spawn_pkg/urdf/assets/moving_jaw_so101_v1.stl" />
      </geometry>
      <material name="green" />
    </visual>
    
    <collision>
      <geometry>
        <mesh filename="/home/duvvuri/bambot_ws/src/Prep_PS_UGV_robo/gazebo_spawn_pkg/urdf/assets/moving_jaw_so101_v1.stl" />
      </geometry>
      <origin xyz="-5.55112e-17 0 0.0189" rpy="9.53145e-17 6.93889e-18 1.24077e-24" />
    </collision>
  </link>

  <link name="L_base">
    <inertial>
      <origin xyz="-0.14932 -0.16812 0.065966" rpy="0 0 0" />
      <mass value="0.147" />
      <inertia ixx="0.000114686" ixy="-4.59787e-07" ixz="4.97151e-06" 
               iyy="0.000136117" iyz="9.75275e-08" izz="0.000130364" />
    </inertial>
    
    <visual>
      <origin xyz="-0.169402 -0.168167 0.0300817" rpy="1.5708 -1.67685e-15 1.5708" />
      <geometry>
        <mesh filename="/home/duvvuri/bambot_ws/src/Prep_PS_UGV_robo/gazebo_spawn_pkg/urdf/assets/base_motor_holder_so101_v1.stl" />
      </geometry>
      <material name="green" />
    </visual>
    <visual>
      <origin xyz="-0.169402 -0.168068 0.0300817" rpy="1.5708 -1.6144e-15 1.5708" />
      <geometry>
        <mesh filename="/home/duvvuri/bambot_ws/src/Prep_PS_UGV_robo/gazebo_spawn_pkg/urdf/assets/base_so101_v2.stl" />
      </geometry>
      <material name="green" />
    </visual>
    <visual>
      <origin xyz="-0.136702 -0.168068 0.0761817" rpy="-8.21148e-16 7.84513e-18 1.249e-15" />
      <geometry>
        <mesh filename="/home/duvvuri/bambot_ws/src/Prep_PS_UGV_robo/gazebo_spawn_pkg/urdf/assets/sts3215_03a_v1.stl" />
      </geometry>
      <material name="black" />
    </visual>
    <visual>
      <origin xyz="-0.19402 -0.168267 0.0798817" rpy="1.5708 -1.35493e-14 1.5708" />
      <geometry>
        <mesh filename="/home/duvvuri/bambot_ws/src/Prep_PS_UGV_robo/gazebo_spawn_pkg/urdf/assets/waveshare_mounting_plate_so101_v2.stl" />
      </geometry>
      <material name="green" />
    </visual>
    
    <collision>
      <geometry>
        <box size="0.08 0.05 0.08"/>
      </geometry>
      <origin xyz="-0.17 -0.168 0.065" rpy="0 0 0" />
    </collision>
  </link>

  <link name="L_baseframe">
    <inertial>
      <mass value="1e-9" />
      <inertia ixx="1e-9" ixy="0" ixz="0" iyy="1e-9" iyz="0" izz="1e-9" />
    </inertial>
  </link>

  <joint name="baseframe_frame" type="fixed">
    <origin xyz="-0.163038 -0.168068 0.0324817" rpy="1.6144e-15 7.84513e-18 1.33799e-15" />
    <parent link="L_base" />
    <child link="L_baseframe" />
  </joint>

  <link name="L_shoulder">
    <inertial>
      <origin xyz="-0.0307604 -1.66727e-05 -0.0252713" rpy="0 0 0" />
      <mass value="0.100006" />
      <inertia ixx="8.3759e-05" ixy="7.55525e-08" ixz="-1.16342e-06" 
               iyy="8.10403e-05" iyz="1.54663e-07" izz="2.39783e-05" />
    </inertial>
    
    <visual>
      <origin xyz="-0.0303992 0.000422241 -0.0417" rpy="1.5708 1.5708 0" />
      <geometry>
        <mesh filename="/home/duvvuri/bambot_ws/src/Prep_PS_UGV_robo/gazebo_spawn_pkg/urdf/assets/sts3215_03a_v1.stl" />
      </geometry>
      <material name="black" />
    </visual>
    <visual>
      <origin xyz="-0.0675992 -0.000177759 0.0158499" rpy="1.5708 -1.5708 0" />
      <geometry>
        <mesh filename="/home/duvvuri/bambot_ws/src/Prep_PS_UGV_robo/gazebo_spawn_pkg/urdf/assets/motor_holder_so101_base_v1.stl" />
      </geometry>
      <material name="green" />
    </visual>
    <visual>
      <origin xyz="0.0122008 2.22413e-05 0.0464" rpy="-1.5708 2.35221e-33 0" />
      <geometry>
        <mesh filename="/home/duvvuri/bambot_ws/src/Prep_PS_UGV_robo/gazebo_spawn_pkg/urdf/assets/rotation_pitch_so101_v1.stl" />
      </geometry>
      <material name="green" />
    </visual>
    
    <collision>
      <geometry>
        <box size="0.06 0.04 0.06"/>
      </geometry>
      <origin xyz="-0.03 0 0" rpy="0 0 0" />
    </collision>
  </link>

  <link name="L_upper_arm">
    <inertial>
      <origin xyz="-0.0898471 -0.00838224 0.0184089" rpy="0 0 0" />
      <mass value="0.103" />
      <inertia ixx="4.08002e-05" ixy="-1.97819e-05" ixz="-4.03016e-08" 
               iyy="0.000147318" iyz="8.97326e-09" izz="0.000142487" />
    </inertial>
    
    <visual>
      <origin xyz="-0.11257 -0.0155 0.0187" rpy="-3.14159 -5.27356e-16 -1.5708" />
      <geometry>
        <mesh filename="/home/duvvuri/bambot_ws/src/Prep_PS_UGV_robo/gazebo_spawn_pkg/urdf/assets/sts3215_03a_v1.stl" />
      </geometry>
      <material name="black" />
    </visual>
    <visual>
      <origin xyz="-0.065085 0.012 0.0182" rpy="3.14159 -0 -1.30911e-30" />
      <geometry>
        <mesh filename="/home/duvvuri/bambot_ws/src/Prep_PS_UGV_robo/gazebo_spawn_pkg/urdf/assets/upper_arm_so101_v1.stl" />
      </geometry>
      <material name="green" />
    </visual>
    
    <collision>
      <geometry>
        <box size="0.12 0.03 0.04"/>
      </geometry>
      <origin xyz="-0.06 0 0.018" rpy="0 0 0" />
    </collision>
  </link>

  <link name="L_lower_arm">
    <inertial>
      <origin xyz="-0.0980701 0.00324376 0.0182831" rpy="0 0 0" />
      <mass value="0.104" />
      <inertia ixx="2.87438e-05" ixy="7.41152e-06" ixz="1.26409e-06" 
               iyy="0.000159844" iyz="-4.90188e-08" izz="0.00014529" />
    </inertial>
    
    <visual>
      <origin xyz="-0.0648499 -0.032 0.0182" rpy="3.14159 -0 6.67202e-31" />
      <geometry>
        <mesh filename="/home/duvvuri/bambot_ws/src/Prep_PS_UGV_robo/gazebo_spawn_pkg/urdf/assets/under_arm_so101_v1.stl" />
      </geometry>
      <material name="green" />
    </visual>
    <visual>
      <origin xyz="-0.0648499 -0.032 0.018" rpy="-3.14159 -2.55351e-15 -2.56146e-31" />
      <geometry>
        <mesh filename="/home/duvvuri/bambot_ws/src/Prep_PS_UGV_robo/gazebo_spawn_pkg/urdf/assets/motor_holder_so101_wrist_v1.stl" />
      </geometry>
      <material name="green" />
    </visual>
    <visual>
      <origin xyz="-0.1224 0.0052 0.0187" rpy="-3.14159 -7.88861e-31 -3.14159" />
      <geometry>
        <mesh filename="/home/duvvuri/bambot_ws/src/Prep_PS_UGV_robo/gazebo_spawn_pkg/urdf/assets/sts3215_03a_v1.stl" />
      </geometry>
      <material name="black" />
    </visual>
    
    <collision>
      <geometry>
        <box size="0.13 0.04 0.04"/>
      </geometry>
      <origin xyz="-0.09 -0.01 0.018" rpy="0 0 0" />
    </collision>
  </link>

  <link name="L_wrist">
    <inertial>
      <origin xyz="-0.000103312 -0.0386143 0.0281156" rpy="0 0 0" />
      <mass value="0.079" />
      <inertia ixx="3.68263e-05" ixy="1.7893e-08" ixz="-5.28128e-08" 
               iyy="2.5391e-05" iyz="3.6412e-06" izz="2.1e-05" />
    </inertial>
    
    <visual>
      <origin xyz="5.55112e-17 -0.0424 0.0306" rpy="1.5708 1.5708 0" />
      <geometry>
        <mesh filename="/home/duvvuri/bambot_ws/src/Prep_PS_UGV_robo/gazebo_spawn_pkg/urdf/assets/sts3215_03a_no_horn_v1.stl" />
      </geometry>
      <material name="black" />
    </visual>
    <visual>
      <origin xyz="0 -0.028 0.0181" rpy="-1.5708 -1.5708 0" />
      <geometry>
        <mesh filename="/home/duvvuri/bambot_ws/src/Prep_PS_UGV_robo/gazebo_spawn_pkg/urdf/assets/wrist_roll_pitch_so101_v2.stl" />
      </geometry>
      <material name="green" />
    </visual>
    
    <collision>
      <geometry>
        <cylinder radius="0.025" length="0.05"/>
      </geometry>
      <origin xyz="0 -0.03 0.03" rpy="0 0 0" />
    </collision>
  </link>

  <link name="L_gripper">
    <inertial>
      <origin xyz="0.000213627 0.000245138 -0.025187" rpy="0 0 0" />
      <mass value="0.087" />
      <inertia ixx="2.75087e-05" ixy="-3.35241e-07" ixz="-5.7352e-06" iyy="4.33657e-05"
        iyz="-5.17847e-08" izz="3.45059e-05" />
    </inertial>
    <visual>
      <origin xyz="0.0077 0.0001 -0.0234" rpy="-1.5708 -5.19179e-17 -1.66533e-16" />
      <geometry>
        <mesh filename="/home/duvvuri/bambot_ws/src/Prep_PS_UGV_robo/gazebo_spawn_pkg/urdf/assets/sts3215_03a_v1.stl" />
      </geometry>
      <material name="black" />
    </visual>
    <collision>
      <origin xyz="0.0077 0.0001 -0.0234" rpy="-1.5708 -5.19179e-17 -1.66533e-16" />
      <geometry>
        <mesh filename="/home/duvvuri/bambot_ws/src/Prep_PS_UGV_robo/gazebo_spawn_pkg/urdf/assets/sts3215_03a_v1.stl" />
      </geometry>
    </collision>
    <visual>
      <origin xyz="0 -0.000218214 0.000949706" rpy="-3.14159 -5.55112e-17 0" />
      <geometry>
        <mesh filename="/home/duvvuri/bambot_ws/src/Prep_PS_UGV_robo/gazebo_spawn_pkg/urdf/assets/wrist_roll_follower_so101_v1.stl" />
      </geometry>
      <material name="green" />
    </visual>
    <collision>
      <origin xyz="0 -0.000218214 0.000949706" rpy="-3.14159 -5.55112e-17 0" />
      <geometry>
        <mesh filename="/home/duvvuri/bambot_ws/src/Prep_PS_UGV_robo/gazebo_spawn_pkg/urdf/assets/wrist_roll_follower_so101_v1.stl" />
      </geometry>
    </collision>
  </link>

  <link name="L_gripperframe">
    <inertial>
      <mass value="1e-9" />
      <inertia ixx="1e-9" ixy="0" ixz="0" iyy="1e-9" iyz="0" izz="1e-9" />
    </inertial>
  </link>

  <joint name="L_gripperframe_frame" type="fixed">
    <origin xyz="-0.0079 -0.000218121 -0.0981274" rpy="-0 1.5708 0" />
    <parent link="L_gripper" />
    <child link="L_gripperframe" />
  </joint>

  <link name="L_moving_jaw_so101_v1">
    <inertial>
      <origin xyz="-0.00157495 -0.0300244 0.0192755" rpy="0 0 0" />
      <mass value="0.012" />
      <inertia ixx="6.61427e-06" ixy="-3.19807e-07" ixz="-5.90717e-09" 
               iyy="1.89032e-06" iyz="-1.09945e-07" izz="5.28738e-06" />
    </inertial>
    
    <visual>
      <origin xyz="-5.55112e-17 0 0.0189" rpy="9.53145e-17 6.93889e-18 1.24077e-24" />
      <geometry>
        <mesh filename="/home/duvvuri/bambot_ws/src/Prep_PS_UGV_robo/gazebo_spawn_pkg/urdf/assets/moving_jaw_so101_v1.stl" />
      </geometry>
      <material name="green" />
    </visual>
    
    <collision>
      <origin xyz="-5.55112e-17 0 0.0189" rpy="9.53145e-17 6.93889e-18 1.24077e-24" />
      <geometry>
        <mesh filename="/home/duvvuri/bambot_ws/src/Prep_PS_UGV_robo/gazebo_spawn_pkg/urdf/assets/moving_jaw_so101_v1.stl" />
      </geometry>
    </collision>
  </link>

  <joint name="L_Rotation" type="revolute">
    <origin xyz="-0.124202 -0.168068 0.0948817" rpy="3.14159 0 0" />
    <parent link="L_base" />
    <child link="L_shoulder" />
    <axis xyz="0 0 1" />
    <limit effort="10" velocity="10" lower="1.22014" upper="5.05986" />
  </joint>

  <joint name="L_Pitch" type="revolute">
    <origin xyz="-0.0303992 -0.0182778 -0.0542" rpy="-1.5708 1.5692 0" />
    <parent link="L_shoulder" />
    <child link="L_upper_arm" />
    <axis xyz="0 0 1" />
    <limit effort="10" velocity="10" lower="1.39467" upper="4.88692" />
  </joint>

  <joint name="L_Elbow" type="revolute">
    <origin xyz="-0.11257 -0.028 2.09886e-16" rpy="0 0 4.71239" />
    <parent link="L_upper_arm" />
    <child link="L_lower_arm" />
    <axis xyz="0 0 1" />
    <limit effort="10" velocity="10" lower="1.39626" upper="4.71239" />
  </joint>

  <joint name="L_Wrist_Pitch" type="revolute">
    <origin xyz="-0.1349 0.0052 8.44651e-17" rpy="0 0 1.57079" />
    <parent link="L_lower_arm" />
    <child link="L_wrist" />
    <axis xyz="0 0 1" />
    <limit effort="10" velocity="10" lower="1.48353" upper="4.79965" />
  </joint>

  <joint name="L_Wrist_Roll" type="revolute">
    <origin xyz="2.77556e-16 -0.0611 0.0181" rpy="1.5708 3.1902695 3.14159" />
    <parent link="L_wrist" />
    <child link="L_gripper" />
    <axis xyz="0 0 1" />
    <limit effort="10" velocity="10" lower="0.39774" upper="5.9828" />
  </joint>

  <joint name="L_Jaw" type="revolute">
    <origin xyz="0.0202 0.0188 -0.0234" rpy="1.5708 3.315 0" />
    <parent link="L_gripper" />
    <child link="L_moving_jaw_so101_v1" />
    <axis xyz="0 0 1" />
    <limit effort="10" velocity="10" lower="3.14" upper="4.88692" />
  </joint>

  <link name="left_motor">
    <visual>
      <geometry>
        <mesh filename="/home/duvvuri/bambot_ws/src/Prep_PS_UGV_robo/gazebo_spawn_pkg/urdf/bambot_assets/Base_Motor.stl" />
      </geometry>
      <origin xyz="0 -0.04 0.1" rpy="3.14159 0 0" />
      <material name="black" />
    </visual>
    
    <collision>
      <geometry>
        <cylinder radius="0.03" length="0.08"/>
      </geometry>
      <origin xyz="0 -0.04 0.1" rpy="3.14159 0 0" />
    </collision>
    
    <inertial>
      <mass value="1.0"/>
      <inertia ixx="0.01" ixy="0.0" ixz="0.0" iyy="0.01" iyz="0.0" izz="0.01"/>
    </inertial>
  </link>

  <joint name="left_motor" type="fixed">
    <parent link="base_link" />
    <child link="left_motor" />
    <origin xyz="-0.1 0.0 -0.03" rpy="0 1.5708 -2.0944" />
  </joint>

  <link name="right_motor">
    <visual>
      <geometry>
        <mesh filename="/home/duvvuri/bambot_ws/src/Prep_PS_UGV_robo/gazebo_spawn_pkg/urdf/bambot_assets/Base_Motor.stl" />
      </geometry>
      <origin xyz="0 -0.04 0.1" rpy="3.14159 0 0" />
      <material name="black" />
    </visual>
    
    <collision>
      <geometry>
        <cylinder radius="0.03" length="0.08"/>
      </geometry>
      <origin xyz="0 -0.04 0.1" rpy="3.14159 0 0" />
    </collision>
    
    <inertial>
      <mass value="1.0"/>
      <inertia ixx="0.01" ixy="0.0" ixz="0.0" iyy="0.01" iyz="0.0" izz="0.01"/>
    </inertial>
  </link>

  <joint name="right_motor" type="fixed">
    <parent link="base_link" />
    <child link="right_motor" />
    <origin xyz="-0.1 -0.48 -0.03" rpy="0 1.5708 2.0944" />
  </joint>

  <link name="back_motor">
    <visual>
      <geometry>
        <mesh filename="/home/duvvuri/bambot_ws/src/Prep_PS_UGV_robo/gazebo_spawn_pkg/urdf/bambot_assets/Base_Motor.stl" />
      </geometry>
      <origin xyz="0 -0.04 0.1" rpy="3.14159 0 0" />
      <material name="black" />
    </visual>
    
    <collision>
      <geometry>
        <cylinder radius="0.03" length="0.08"/>
      </geometry>
      <origin xyz="0 -0.04 0.1" rpy="3.14159 0 0" />
    </collision>
    
    <inertial>
      <mass value="1.0"/>
      <inertia ixx="0.01" ixy="0.0" ixz="0.0" iyy="0.01" iyz="0.0" izz="0.01"/>
    </inertial>
  </link>

  <joint name="back_motor" type="fixed">
    <parent link="base_link" />
    <child link="back_motor" />
    <origin xyz="-0.52 -0.25 -0.03" rpy="0 1.5708 0" />
  </joint>

  <link name="left_wheel">
    <visual>
      <geometry>
        <mesh filename="/home/duvvuri/bambot_ws/src/Prep_PS_UGV_robo/gazebo_spawn_pkg/urdf/bambot_assets/BambotWheel.stl" scale="0.001 0.001 0.001" />
      </geometry>
      <material name="black" />
    </visual>
    
    <collision>
      <geometry>
        <cylinder radius="0.05" length="0.02"/>
      </geometry>
    </collision>
    
    <inertial>
      <mass value="1.0"/>
      <inertia ixx="0.00166" ixy="0.0" ixz="0.0" iyy="0.00166" iyz="0.0" izz="0.003125"/>
    </inertial>
  </link>

  <link name="right_wheel">
    <visual>
      <geometry>
        <mesh filename="/home/duvvuri/bambot_ws/src/Prep_PS_UGV_robo/gazebo_spawn_pkg/urdf/bambot_assets/BambotWheel.stl" scale="0.001 0.001 0.001" />
      </geometry>
      <material name="black" />
    </visual>
    
    <collision>
      <geometry>
        <cylinder radius="0.05" length="0.02"/>
      </geometry>
    </collision>
    
    <inertial>
      <mass value="1.0"/>
      <inertia ixx="0.00166" ixy="0.0" ixz="0.0" iyy="0.00166" iyz="0.0" izz="0.003125"/>
    </inertial>
  </link>

  <link name="back_wheel">
    <visual>
      <geometry>
        <mesh filename="/home/duvvuri/bambot_ws/src/Prep_PS_UGV_robo/gazebo_spawn_pkg/urdf/bambot_assets/BambotWheel.stl" scale="0.001 0.001 0.001" />
      </geometry>
      <material name="black" />
    </visual>
    
    <collision>
      <geometry>
        <cylinder radius="0.05" length="0.02"/>
      </geometry>
    </collision>
    
    <inertial>
      <mass value="1.0"/>
      <inertia ixx="0.00166" ixy="0.0" ixz="0.0" iyy="0.00166" iyz="0.0" izz="0.003125"/>
    </inertial>
  </link>

  <joint name="R_Rotation" type="revolute">
    <origin xyz="-0.124202 -0.168068 0.0948817" rpy="3.14159 0 0" />
    <parent link="R_base" />
    <child link="R_shoulder" />
    <axis xyz="0 0 1" />
    <limit effort="10" velocity="10" lower="1.22014" upper="5.05986" />
  </joint>

  <joint name="R_Pitch" type="revolute">
    <origin xyz="-0.0303992 -0.0182778 -0.0542" rpy="-1.5708 1.5692 0" />
    <parent link="R_shoulder" />
    <child link="R_upper_arm" />
    <axis xyz="0 0 1" />
    <limit effort="10" velocity="10" lower="1.39467" upper="4.88692" />
  </joint>

  <joint name="R_Elbow" type="revolute">
    <origin xyz="-0.11257 -0.028 2.09886e-16" rpy="0 0 4.71239" />
    <parent link="R_upper_arm" />
    <child link="R_lower_arm" />
    <axis xyz="0 0 1" />
    <limit effort="10" velocity="10" lower="1.39626" upper="4.71239" />
  </joint>

  <joint name="R_Wrist_Pitch" type="revolute">
    <origin xyz="-0.1349 0.0052 8.44651e-17" rpy="0 0 1.57079" />
    <parent link="R_lower_arm" />
    <child link="R_wrist" />
    <axis xyz="0 0 1" />
    <limit effort="10" velocity="10" lower="1.48353" upper="4.79965" />
  </joint>

  <joint name="R_Wrist_Roll" type="revolute">
    <origin xyz="2.77556e-16 -0.0611 0.0181" rpy="1.5708 3.1902695 3.14159" />
    <parent link="R_wrist" />
    <child link="R_gripper" />
    <axis xyz="0 0 1" />
    <limit effort="10" velocity="10" lower="0.39774" upper="5.9828" />
  </joint>

  <joint name="R_Jaw" type="revolute">
    <origin xyz="0.0202 0.0188 -0.0234" rpy="1.5708 3.315 0" />
    <parent link="R_gripper" />
    <child link="R_moving_jaw_so101_v1" />
    <axis xyz="0 0 1" />
    <limit effort="10" velocity="10" lower="3.14" upper="4.88692" />
  </joint>

  <joint name="left_wheel_joint" type="continuous">
    <parent link="base_link" />
    <child link="left_wheel" />
    <origin xyz="-0.1 0.0 -0.03" rpy="0 1.5708 -2.0944" />
    <axis xyz="0 0 1" />
  </joint>

  <joint name="right_wheel_joint" type="continuous">
    <parent link="base_link" />
    <child link="right_wheel" />
    <origin xyz="-0.1 -0.48 -0.03" rpy="0 1.5708 2.0944" />
    <axis xyz="0 0 1" />
  </joint>

  <joint name="back_wheel_joint" type="continuous">
    <parent link="base_link" />
    <child link="back_wheel" />
    <origin xyz="-0.52 -0.25 -0.03" rpy="0 1.5708 0" />
    <axis xyz="0 0 1" />
  </joint>

  <joint name="L_to_base" type="fixed">
    <parent link="base_link" />
    <child link="L_base" />
    <origin xyz="-0.01 -0.235 0.67" rpy="0 3.14158 3.14159" />
  </joint>

  <link name="camera_link">
    <visual>
      <geometry>
        <box size="0.1 0.1 0.1"/>
      </geometry>
      <origin xyz="0 0 0" rpy="0 0 0" />
    </visual>
    <collision>
      <geometry>
        <box size="0.1 0.1 0.1"/>
      </geometry>
      <origin xyz="0 0 0" rpy="0 0 0" />
    </collision>

    <inertial>
      <mass value="0.1"/>
      <inertia 
        ixx="0.003" ixy="0.0"  ixz="0.0"
        iyy="0.003" iyz="0.0"
        izz="0.003"/>
    </inertial>
  </link>

  <joint name="base_to_cam" type="revolute">
    <origin xyz="-0.12 -0.25 0.9" rpy="0 0 0" />
    <parent link="base_link" />
    <child link="camera_link" />
    <axis xyz="0 1 0" />
    <limit effort="10" velocity="10" lower="-0.5" upper="0.9" />
  </joint>

  <gazebo reference="camera_link">
    <sensor type="depth" name="rgbd_camera">
      <update_rate>60</update_rate>
      <camera>
        <horizontal_fov>1.5</horizontal_fov>
        <image>
          <width>1920</width>
          <height>1080</height>
          <format>R8G8B8</format>
        </image>
        <clip>
          <near>0.1</near>
          <far>10.0</far>
        </clip>
      </camera>

      <plugin name="gazebo_ros_camera" filename="libgazebo_ros_camera.so">
        <ros>
          <namespace>/</namespace>
          <remapping>image_raw:=/camera/color/image_raw</remapping>
          <remapping>camera_info:=/camera/color/camera_info</remapping>
          <remapping>depth/image_raw:=/camera/depth/image_raw</remapping>
          <remapping>depth/camera_info:=/camera/depth/camera_info</remapping>
          <remapping>points:=/camera/depth/points</remapping>
        </ros>
      </plugin>
    </sensor>
  </gazebo>



  <link name="lidar_link">
    <inertial>
      <mass value="0.1"/>
      <inertia 
        ixx="0.003" ixy="0.0"  ixz="0.0"
        iyy="0.003" iyz="0.0"
        izz="0.003"/>
    </inertial>
    <visual>
      <origin xyz="0 0 0" rpy="0 0 0"/>
      <geometry>
        <cylinder length="0.05" radius="0.04"/>
      </geometry>
      <material name="black"/>
    </visual>
    <collision>
      <origin xyz="0 0 0" rpy="0 0 0"/>
      <geometry>
        <cylinder length="0.05" radius="0.04"/>
      </geometry>
    </collision>
  </link>

  <joint name="base_to_lidar" type="fixed">
    <parent link="base_link" />
    <child link="lidar_link" />
    <origin xyz="-0.25 -0.25 0.2" rpy="0 0 0" />
  </joint>


  <gazebo reference="lidar_link">
    <sensor type="ray" name="lidar_sensor">
      <pose>0 0 0 0 0 0</pose>
      <visualize>true</visualize>
      <update_rate>20</update_rate>

      <ray>
        <scan>
          <horizontal>
            <samples>720</samples>         <!-- Number of beams -->
            <resolution>1</resolution>
            <min_angle>-3.14</min_angle>
            <max_angle>3.14</max_angle>
          </horizontal>
        </scan>
        <range>
          <min>0.12</min>
          <max>10.0</max>
          <resolution>0.01</resolution>
        </range>
        <noise>
          <type>gaussian</type>
          <mean>0.0</mean>
          <stddev>0.01</stddev>
        </noise>
      </ray>

      <!-- ROS2 plugin -->
      <plugin name="gazebo_ros_lidar" filename="libgazebo_ros_ray_sensor.so">
        <ros>
          <namespace>/</namespace>
          <remapping>~/out:=/scan</remapping>
        </ros>
        <output_type>sensor_msgs/LaserScan</output_type>
        <frame_name>lidar_link</frame_name>
      </plugin>
    </sensor>
  </gazebo>

    
  <link name="imu_link">
    <inertial>
      <mass value="0.01"/>
      <inertia ixx="0.0001" ixy="0.0" ixz="0.0" iyy="0.0001" iyz="0.0" izz="0.0001"/>
    </inertial>
    <visual>
      <origin xyz="0 0 0" rpy="0 0 0"/>
      <geometry>
        <box size="0.02 0.02 0.01"/>
      </geometry>
      <material name="black"/>
    </visual>
    <collision>
      <origin xyz="0 0 0" rpy="0 0 0"/>
      <geometry>
        <box size="0.02 0.02 0.01"/>
      </geometry>
    </collision>
  </link>

  <joint name="imu_joint" type="fixed">
    <parent link="base_link"/>
    <child link="imu_link"/>
    <origin xyz="0 0 0.1" rpy="0 0 0"/> <!-- 10 cm above base_link -->
  </joint>

  <gazebo reference="imu_link">
    <sensor type="imu" name="imu_sensor">
      <always_on>true</always_on>
      <update_rate>100</update_rate> <!-- Hz -->

      <imu>
        <noise>
          <type>gaussian</type>
          <rate> <!-- Gyroscope -->
            <mean>0.0</mean>
            <stddev>0.0002</stddev>
            <bias_mean>0.0000075</bias_mean>
            <bias_stddev>0.0000008</bias_stddev>
          </rate>
          <accel> <!-- Accelerometer -->
            <mean>0.0</mean>
            <stddev>0.017</stddev>
            <bias_mean>0.1</bias_mean>
            <bias_stddev>0.001</bias_stddev>
          </accel>
        </noise>
      </imu>

      <!-- ✅ Updated plugin for ROS 2 -->
      <plugin name="imu_plugin" filename="libgazebo_ros_imu_sensor.so">
        <ros>
          <namespace>/</namespace>
          <remapping>~/out:=imu/data</remapping>
        </ros>
        <frame_id>imu_link</frame_id>
      </plugin>

    </sensor>
  </gazebo>



  <!-- ros2_control for actuators-->
  <gazebo>
    <plugin name="gazebo_ros2_control" filename="libgazebo_ros2_control.so">
      <parameters>/home/duvvuri/bambot_ws/src/Prep_PS_UGV_robo/gazebo_spawn_pkg/config/bambot_controllers.yaml</parameters>
    </plugin>
  </gazebo>

  <ros2_control name="BambotHardwareInterface" type="system">
    <hardware>
      <plugin>gazebo_ros2_control/GazeboSystem</plugin>
    </hardware>

    <joint name="base_to_cam">
      <command_interface name="position"/>
      <state_interface name="position"/>
      <state_interface name="velocity"/>
    </joint>
    
    <joint name="R_Rotation">
      <command_interface name="position"/>
      <state_interface name="position"/>
      <state_interface name="velocity"/>
    </joint>
    <joint name="R_Pitch">
      <command_interface name="position"/>
      <state_interface name="position"/>
      <state_interface name="velocity"/>
    </joint>
    <joint name="R_Elbow">
      <command_interface name="position"/>
      <state_interface name="position"/>
      <state_interface name="velocity"/>
    </joint>
    <joint name="R_Wrist_Pitch">
      <command_interface name="position"/>
      <state_interface name="position"/>
      <state_interface name="velocity"/>
    </joint>
    <joint name="R_Wrist_Roll">
      <command_interface name="position"/>
      <state_interface name="position"/>
      <state_interface name="velocity"/>
    </joint>
    <joint name="R_Jaw">
      <command_interface name="position"/>
      <state_interface name="position"/>
      <state_interface name="velocity"/>
    </joint>

    <!-- Left arm joints -->
    <joint name="L_Rotation">
      <command_interface name="position"/>
      <state_interface name="position"/>
      <state_interface name="velocity"/>
    </joint>
    <joint name="L_Pitch">
      <command_interface name="position"/>
      <state_interface name="position"/>
      <state_interface name="velocity"/>
    </joint>
    <joint name="L_Elbow">
      <command_interface name="position"/>
      <state_interface name="position"/>
      <state_interface name="velocity"/>
    </joint>
    <joint name="L_Wrist_Pitch">
      <command_interface name="position"/>
      <state_interface name="position"/>
      <state_interface name="velocity"/>
    </joint>
    <joint name="L_Wrist_Roll">
      <command_interface name="position"/>
      <state_interface name="position"/>
      <state_interface name="velocity"/>
    </joint>
    <joint name="L_Jaw">
      <command_interface name="position"/>
      <state_interface name="position"/>
      <state_interface name="velocity"/>
    </joint>

    <!-- Motor wheels -->
    <joint name="left_wheel_joint">
      <command_interface name="velocity"/>
      <state_interface name="position"/>
      <state_interface name="velocity"/>
    </joint>
    <joint name="right_wheel_joint">
      <command_interface name="velocity"/>
      <state_interface name="position"/>
      <state_interface name="velocity"/>
    </joint>
    <joint name="back_wheel_joint">
      <command_interface name="velocity"/>
      <state_interface name="position"/>
      <state_interface name="velocity"/>
    </joint>
  </ros2_control>



</robot>
